[2024-12-23T10:12:59.346+0000] {local_task_job_runner.py:123} INFO - ::group::Pre task execution logs
[2024-12-23T10:12:59.358+0000] {taskinstance.py:2613} INFO - Dependencies all met for dep_context=non-requeueable deps ti=<TaskInstance: namu_crawling.initialize_if_needed scheduled__2024-12-22T00:00:00+00:00 [queued]>
[2024-12-23T10:12:59.363+0000] {taskinstance.py:2613} INFO - Dependencies all met for dep_context=requeueable deps ti=<TaskInstance: namu_crawling.initialize_if_needed scheduled__2024-12-22T00:00:00+00:00 [queued]>
[2024-12-23T10:12:59.364+0000] {taskinstance.py:2866} INFO - Starting attempt 1 of 2
[2024-12-23T10:12:59.372+0000] {taskinstance.py:2889} INFO - Executing <Task(PythonOperator): initialize_if_needed> on 2024-12-22 00:00:00+00:00
[2024-12-23T10:12:59.378+0000] {warnings.py:112} WARNING - /home/***/.local/lib/python3.12/site-packages/***/task/task_runner/standard_task_runner.py:70: DeprecationWarning: This process (pid=139) is multi-threaded, use of fork() may lead to deadlocks in the child.
  pid = os.fork()

[2024-12-23T10:12:59.379+0000] {standard_task_runner.py:72} INFO - Started process 145 to run task
[2024-12-23T10:12:59.380+0000] {standard_task_runner.py:104} INFO - Running: ['***', 'tasks', 'run', 'namu_crawling', 'initialize_if_needed', 'scheduled__2024-12-22T00:00:00+00:00', '--job-id', '8', '--raw', '--subdir', 'DAGS_FOLDER/namu_crawling_dag.py', '--cfg-path', '/tmp/tmprr_mwsb2']
[2024-12-23T10:12:59.380+0000] {standard_task_runner.py:105} INFO - Job 8: Subtask initialize_if_needed
[2024-12-23T10:12:59.411+0000] {task_command.py:467} INFO - Running <TaskInstance: namu_crawling.initialize_if_needed scheduled__2024-12-22T00:00:00+00:00 [running]> on host 33f70545a420
[2024-12-23T10:12:59.461+0000] {taskinstance.py:3132} INFO - Exporting env vars: AIRFLOW_CTX_DAG_OWNER='***' AIRFLOW_CTX_DAG_ID='namu_crawling' AIRFLOW_CTX_TASK_ID='initialize_if_needed' AIRFLOW_CTX_EXECUTION_DATE='2024-12-22T00:00:00+00:00' AIRFLOW_CTX_TRY_NUMBER='1' AIRFLOW_CTX_DAG_RUN_ID='scheduled__2024-12-22T00:00:00+00:00'
[2024-12-23T10:12:59.462+0000] {logging_mixin.py:190} INFO - Task instance is in running state
[2024-12-23T10:12:59.462+0000] {logging_mixin.py:190} INFO -  Previous state of the Task instance: queued
[2024-12-23T10:12:59.462+0000] {logging_mixin.py:190} INFO - Current task name:initialize_if_needed state:running start_date:2024-12-23 10:12:59.359041+00:00
[2024-12-23T10:12:59.462+0000] {logging_mixin.py:190} INFO - Dag name:namu_crawling and current dag run status:running
[2024-12-23T10:12:59.463+0000] {taskinstance.py:731} INFO - ::endgroup::
[2024-12-23T10:13:19.522+0000] {local_task_job_runner.py:346} WARNING - State of this instance has been externally set to None. Terminating instance.
[2024-12-23T10:13:19.523+0000] {local_task_job_runner.py:245} INFO - ::endgroup::
[2024-12-23T10:13:19.524+0000] {process_utils.py:132} INFO - Sending 15 to group 145. PIDs of all processes in the group: [149, 145]
[2024-12-23T10:13:19.524+0000] {process_utils.py:87} INFO - Sending the signal 15 to group 145
[2024-12-23T10:13:19.525+0000] {taskinstance.py:3093} ERROR - Received SIGTERM. Terminating subprocesses.
[2024-12-23T10:13:19.545+0000] {taskinstance.py:3311} ERROR - Task failed with exception
Traceback (most recent call last):
  File "/home/airflow/.local/lib/python3.12/site-packages/airflow/models/taskinstance.py", line 762, in _execute_task
    result = _execute_callable(context=context, **execute_callable_kwargs)
             ^^^^^^^^^^^^^^^^^^^^^^^^^^^^^^^^^^^^^^^^^^^^^^^^^^^^^^^^^^^^^
  File "/home/airflow/.local/lib/python3.12/site-packages/airflow/models/taskinstance.py", line 733, in _execute_callable
    return ExecutionCallableRunner(
           ^^^^^^^^^^^^^^^^^^^^^^^^
  File "/home/airflow/.local/lib/python3.12/site-packages/airflow/utils/operator_helpers.py", line 252, in run
    return self.func(*args, **kwargs)
           ^^^^^^^^^^^^^^^^^^^^^^^^^^
  File "/home/airflow/.local/lib/python3.12/site-packages/airflow/models/baseoperator.py", line 422, in wrapper
    return func(self, *args, **kwargs)
           ^^^^^^^^^^^^^^^^^^^^^^^^^^^
  File "/home/airflow/.local/lib/python3.12/site-packages/airflow/operators/python.py", line 238, in execute
    return_value = self.execute_callable()
                   ^^^^^^^^^^^^^^^^^^^^^^^
  File "/home/airflow/.local/lib/python3.12/site-packages/airflow/operators/python.py", line 256, in execute_callable
    return runner.run(*self.op_args, **self.op_kwargs)
           ^^^^^^^^^^^^^^^^^^^^^^^^^^^^^^^^^^^^^^^^^^^
  File "/home/airflow/.local/lib/python3.12/site-packages/airflow/utils/operator_helpers.py", line 252, in run
    return self.func(*args, **kwargs)
           ^^^^^^^^^^^^^^^^^^^^^^^^^^
  File "/opt/airflow/dags/namu_crawling_dag.py", line 33, in initialize_and_fetch_recent
    crawler = NamuCrawler()
              ^^^^^^^^^^^^^
  File "/opt/airflow/dags/crawling/sel.py", line 112, in __init__
    self.driver = webdriver.Chrome(options=self.chrome_options)
                  ^^^^^^^^^^^^^^^^^^^^^^^^^^^^^^^^^^^^^^^^^^^^^
  File "/home/airflow/.local/lib/python3.12/site-packages/selenium/webdriver/chrome/webdriver.py", line 45, in __init__
    super().__init__(
  File "/home/airflow/.local/lib/python3.12/site-packages/selenium/webdriver/chromium/webdriver.py", line 50, in __init__
    if finder.get_browser_path():
       ^^^^^^^^^^^^^^^^^^^^^^^^^
  File "/home/airflow/.local/lib/python3.12/site-packages/selenium/webdriver/common/driver_finder.py", line 47, in get_browser_path
    return self._binary_paths()["browser_path"]
           ^^^^^^^^^^^^^^^^^^^^
  File "/home/airflow/.local/lib/python3.12/site-packages/selenium/webdriver/common/driver_finder.py", line 67, in _binary_paths
    output = SeleniumManager().binary_paths(self._to_args())
             ^^^^^^^^^^^^^^^^^^^^^^^^^^^^^^^^^^^^^^^^^^^^^^^
  File "/home/airflow/.local/lib/python3.12/site-packages/selenium/webdriver/common/selenium_manager.py", line 55, in binary_paths
    return self._run(args)
           ^^^^^^^^^^^^^^^
  File "/home/airflow/.local/lib/python3.12/site-packages/selenium/webdriver/common/selenium_manager.py", line 119, in _run
    completed_proc = subprocess.run(args, capture_output=True)
                     ^^^^^^^^^^^^^^^^^^^^^^^^^^^^^^^^^^^^^^^^^
  File "/usr/local/lib/python3.12/subprocess.py", line 550, in run
    stdout, stderr = process.communicate(input, timeout=timeout)
                     ^^^^^^^^^^^^^^^^^^^^^^^^^^^^^^^^^^^^^^^^^^^
  File "/usr/local/lib/python3.12/subprocess.py", line 1209, in communicate
    stdout, stderr = self._communicate(input, endtime, timeout)
                     ^^^^^^^^^^^^^^^^^^^^^^^^^^^^^^^^^^^^^^^^^^
  File "/usr/local/lib/python3.12/subprocess.py", line 2115, in _communicate
    ready = selector.select(timeout)
            ^^^^^^^^^^^^^^^^^^^^^^^^
  File "/usr/local/lib/python3.12/selectors.py", line 415, in select
    fd_event_list = self._selector.poll(timeout)
                    ^^^^^^^^^^^^^^^^^^^^^^^^^^^^
  File "/home/airflow/.local/lib/python3.12/site-packages/airflow/models/taskinstance.py", line 3095, in signal_handler
    raise AirflowTaskTerminated("Task received SIGTERM signal")
airflow.exceptions.AirflowTaskTerminated: Task received SIGTERM signal
[2024-12-23T10:13:19.554+0000] {logging_mixin.py:190} INFO - Task instance in failure state
[2024-12-23T10:13:19.554+0000] {logging_mixin.py:190} INFO - Task start:2024-12-23 10:12:59.359041+00:00 end:2024-12-23 10:13:19.553671+00:00 duration:20.19463
[2024-12-23T10:13:19.554+0000] {logging_mixin.py:190} INFO - Task:<Task(PythonOperator): initialize_if_needed> dag:<DAG: namu_crawling> dagrun:<DagRun namu_crawling @ 2024-12-22 00:00:00+00:00: scheduled__2024-12-22T00:00:00+00:00, state:running, queued_at: 2024-12-23 10:12:56.065682+00:00. externally triggered: False>
[2024-12-23T10:13:19.554+0000] {logging_mixin.py:190} INFO - Failure caused by Task received SIGTERM signal
[2024-12-23T10:13:19.555+0000] {taskinstance.py:1225} INFO - Marking task as UP_FOR_RETRY. dag_id=namu_crawling, task_id=initialize_if_needed, run_id=scheduled__2024-12-22T00:00:00+00:00, execution_date=20241222T000000, start_date=20241223T101259, end_date=20241223T101319
[2024-12-23T10:13:19.562+0000] {taskinstance.py:340} INFO - ::group::Post task execution logs
[2024-12-23T10:13:19.562+0000] {standard_task_runner.py:124} ERROR - Failed to execute job 8 for task initialize_if_needed ((psycopg2.errors.ForeignKeyViolation) insert or update on table "task_fail" violates foreign key constraint "task_fail_ti_fkey"
DETAIL:  Key (dag_id, task_id, run_id, map_index)=(namu_crawling, initialize_if_needed, scheduled__2024-12-22T00:00:00+00:00, -1) is not present in table "task_instance".

[SQL: INSERT INTO task_fail (task_id, dag_id, run_id, map_index, start_date, end_date, duration) VALUES (%(task_id)s, %(dag_id)s, %(run_id)s, %(map_index)s, %(start_date)s, %(end_date)s, %(duration)s) RETURNING task_fail.id]
[parameters: {'task_id': 'initialize_if_needed', 'dag_id': 'namu_crawling', 'run_id': 'scheduled__2024-12-22T00:00:00+00:00', 'map_index': -1, 'start_date': datetime.datetime(2024, 12, 23, 10, 12, 59, 359041, tzinfo=Timezone('UTC')), 'end_date': datetime.datetime(2024, 12, 23, 10, 13, 19, 553671, tzinfo=Timezone('UTC')), 'duration': 20}]
(Background on this error at: https://sqlalche.me/e/14/gkpj); 145)
Traceback (most recent call last):
  File "/home/airflow/.local/lib/python3.12/site-packages/airflow/models/taskinstance.py", line 273, in _run_raw_task
    TaskInstance._execute_task_with_callbacks(
  File "/home/airflow/.local/lib/python3.12/site-packages/airflow/models/taskinstance.py", line 3159, in _execute_task_with_callbacks
    result = self._execute_task(context, task_orig)
             ^^^^^^^^^^^^^^^^^^^^^^^^^^^^^^^^^^^^^^
  File "/home/airflow/.local/lib/python3.12/site-packages/airflow/models/taskinstance.py", line 3183, in _execute_task
    return _execute_task(self, context, task_orig)
           ^^^^^^^^^^^^^^^^^^^^^^^^^^^^^^^^^^^^^^^
  File "/home/airflow/.local/lib/python3.12/site-packages/airflow/models/taskinstance.py", line 762, in _execute_task
    result = _execute_callable(context=context, **execute_callable_kwargs)
             ^^^^^^^^^^^^^^^^^^^^^^^^^^^^^^^^^^^^^^^^^^^^^^^^^^^^^^^^^^^^^
  File "/home/airflow/.local/lib/python3.12/site-packages/airflow/models/taskinstance.py", line 733, in _execute_callable
    return ExecutionCallableRunner(
           ^^^^^^^^^^^^^^^^^^^^^^^^
  File "/home/airflow/.local/lib/python3.12/site-packages/airflow/utils/operator_helpers.py", line 252, in run
    return self.func(*args, **kwargs)
           ^^^^^^^^^^^^^^^^^^^^^^^^^^
  File "/home/airflow/.local/lib/python3.12/site-packages/airflow/models/baseoperator.py", line 422, in wrapper
    return func(self, *args, **kwargs)
           ^^^^^^^^^^^^^^^^^^^^^^^^^^^
  File "/home/airflow/.local/lib/python3.12/site-packages/airflow/operators/python.py", line 238, in execute
    return_value = self.execute_callable()
                   ^^^^^^^^^^^^^^^^^^^^^^^
  File "/home/airflow/.local/lib/python3.12/site-packages/airflow/operators/python.py", line 256, in execute_callable
    return runner.run(*self.op_args, **self.op_kwargs)
           ^^^^^^^^^^^^^^^^^^^^^^^^^^^^^^^^^^^^^^^^^^^
  File "/home/airflow/.local/lib/python3.12/site-packages/airflow/utils/operator_helpers.py", line 252, in run
    return self.func(*args, **kwargs)
           ^^^^^^^^^^^^^^^^^^^^^^^^^^
  File "/opt/airflow/dags/namu_crawling_dag.py", line 33, in initialize_and_fetch_recent
    crawler = NamuCrawler()
              ^^^^^^^^^^^^^
  File "/opt/airflow/dags/crawling/sel.py", line 112, in __init__
    self.driver = webdriver.Chrome(options=self.chrome_options)
                  ^^^^^^^^^^^^^^^^^^^^^^^^^^^^^^^^^^^^^^^^^^^^^
  File "/home/airflow/.local/lib/python3.12/site-packages/selenium/webdriver/chrome/webdriver.py", line 45, in __init__
    super().__init__(
  File "/home/airflow/.local/lib/python3.12/site-packages/selenium/webdriver/chromium/webdriver.py", line 50, in __init__
    if finder.get_browser_path():
       ^^^^^^^^^^^^^^^^^^^^^^^^^
  File "/home/airflow/.local/lib/python3.12/site-packages/selenium/webdriver/common/driver_finder.py", line 47, in get_browser_path
    return self._binary_paths()["browser_path"]
           ^^^^^^^^^^^^^^^^^^^^
  File "/home/airflow/.local/lib/python3.12/site-packages/selenium/webdriver/common/driver_finder.py", line 67, in _binary_paths
    output = SeleniumManager().binary_paths(self._to_args())
             ^^^^^^^^^^^^^^^^^^^^^^^^^^^^^^^^^^^^^^^^^^^^^^^
  File "/home/airflow/.local/lib/python3.12/site-packages/selenium/webdriver/common/selenium_manager.py", line 55, in binary_paths
    return self._run(args)
           ^^^^^^^^^^^^^^^
  File "/home/airflow/.local/lib/python3.12/site-packages/selenium/webdriver/common/selenium_manager.py", line 119, in _run
    completed_proc = subprocess.run(args, capture_output=True)
                     ^^^^^^^^^^^^^^^^^^^^^^^^^^^^^^^^^^^^^^^^^
  File "/usr/local/lib/python3.12/subprocess.py", line 550, in run
    stdout, stderr = process.communicate(input, timeout=timeout)
                     ^^^^^^^^^^^^^^^^^^^^^^^^^^^^^^^^^^^^^^^^^^^
  File "/usr/local/lib/python3.12/subprocess.py", line 1209, in communicate
    stdout, stderr = self._communicate(input, endtime, timeout)
                     ^^^^^^^^^^^^^^^^^^^^^^^^^^^^^^^^^^^^^^^^^^
  File "/usr/local/lib/python3.12/subprocess.py", line 2115, in _communicate
    ready = selector.select(timeout)
            ^^^^^^^^^^^^^^^^^^^^^^^^
  File "/usr/local/lib/python3.12/selectors.py", line 415, in select
    fd_event_list = self._selector.poll(timeout)
                    ^^^^^^^^^^^^^^^^^^^^^^^^^^^^
  File "/home/airflow/.local/lib/python3.12/site-packages/airflow/models/taskinstance.py", line 3095, in signal_handler
    raise AirflowTaskTerminated("Task received SIGTERM signal")
airflow.exceptions.AirflowTaskTerminated: Task received SIGTERM signal

During handling of the above exception, another exception occurred:

Traceback (most recent call last):
  File "/home/airflow/.local/lib/python3.12/site-packages/sqlalchemy/engine/base.py", line 1910, in _execute_context
    self.dialect.do_execute(
  File "/home/airflow/.local/lib/python3.12/site-packages/sqlalchemy/engine/default.py", line 736, in do_execute
    cursor.execute(statement, parameters)
psycopg2.errors.ForeignKeyViolation: insert or update on table "task_fail" violates foreign key constraint "task_fail_ti_fkey"
DETAIL:  Key (dag_id, task_id, run_id, map_index)=(namu_crawling, initialize_if_needed, scheduled__2024-12-22T00:00:00+00:00, -1) is not present in table "task_instance".


The above exception was the direct cause of the following exception:

Traceback (most recent call last):
  File "/home/airflow/.local/lib/python3.12/site-packages/airflow/task/task_runner/standard_task_runner.py", line 117, in _start_by_fork
    ret = args.func(args, dag=self.dag)
          ^^^^^^^^^^^^^^^^^^^^^^^^^^^^^
  File "/home/airflow/.local/lib/python3.12/site-packages/airflow/cli/cli_config.py", line 49, in command
    return func(*args, **kwargs)
           ^^^^^^^^^^^^^^^^^^^^^
  File "/home/airflow/.local/lib/python3.12/site-packages/airflow/utils/cli.py", line 116, in wrapper
    return f(*args, **kwargs)
           ^^^^^^^^^^^^^^^^^^
  File "/home/airflow/.local/lib/python3.12/site-packages/airflow/cli/commands/task_command.py", line 483, in task_run
    task_return_code = _run_task_by_selected_method(args, _dag, ti)
                       ^^^^^^^^^^^^^^^^^^^^^^^^^^^^^^^^^^^^^^^^^^^^
  File "/home/airflow/.local/lib/python3.12/site-packages/airflow/cli/commands/task_command.py", line 256, in _run_task_by_selected_method
    return _run_raw_task(args, ti)
           ^^^^^^^^^^^^^^^^^^^^^^^
  File "/home/airflow/.local/lib/python3.12/site-packages/airflow/cli/commands/task_command.py", line 341, in _run_raw_task
    return ti._run_raw_task(
           ^^^^^^^^^^^^^^^^^
  File "/home/airflow/.local/lib/python3.12/site-packages/airflow/utils/session.py", line 97, in wrapper
    return func(*args, session=session, **kwargs)
           ^^^^^^^^^^^^^^^^^^^^^^^^^^^^^^^^^^^^^^
  File "/home/airflow/.local/lib/python3.12/site-packages/airflow/models/taskinstance.py", line 3005, in _run_raw_task
    return _run_raw_task(
           ^^^^^^^^^^^^^^
  File "/home/airflow/.local/lib/python3.12/site-packages/airflow/models/taskinstance.py", line 327, in _run_raw_task
    ti.handle_failure(e, test_mode, context, session=session)
  File "/home/airflow/.local/lib/python3.12/site-packages/airflow/utils/session.py", line 94, in wrapper
    return func(*args, **kwargs)
           ^^^^^^^^^^^^^^^^^^^^^
  File "/home/airflow/.local/lib/python3.12/site-packages/airflow/models/taskinstance.py", line 3428, in handle_failure
    _handle_failure(
  File "/home/airflow/.local/lib/python3.12/site-packages/airflow/utils/session.py", line 94, in wrapper
    return func(*args, **kwargs)
           ^^^^^^^^^^^^^^^^^^^^^
  File "/home/airflow/.local/lib/python3.12/site-packages/airflow/api_internal/internal_api_call.py", line 166, in wrapper
    return func(*args, **kwargs)
           ^^^^^^^^^^^^^^^^^^^^^
  File "/home/airflow/.local/lib/python3.12/site-packages/airflow/models/taskinstance.py", line 1243, in _handle_failure
    TaskInstance.save_to_db(failure_context["ti"], session)
  File "/home/airflow/.local/lib/python3.12/site-packages/airflow/api_internal/internal_api_call.py", line 166, in wrapper
    return func(*args, **kwargs)
           ^^^^^^^^^^^^^^^^^^^^^
  File "/home/airflow/.local/lib/python3.12/site-packages/airflow/utils/session.py", line 94, in wrapper
    return func(*args, **kwargs)
           ^^^^^^^^^^^^^^^^^^^^^
  File "/home/airflow/.local/lib/python3.12/site-packages/airflow/models/taskinstance.py", line 3400, in save_to_db
    session.flush()
  File "/home/airflow/.local/lib/python3.12/site-packages/sqlalchemy/orm/session.py", line 3449, in flush
    self._flush(objects)
  File "/home/airflow/.local/lib/python3.12/site-packages/sqlalchemy/orm/session.py", line 3588, in _flush
    with util.safe_reraise():
         ^^^^^^^^^^^^^^^^^^^
  File "/home/airflow/.local/lib/python3.12/site-packages/sqlalchemy/util/langhelpers.py", line 70, in __exit__
    compat.raise_(
  File "/home/airflow/.local/lib/python3.12/site-packages/sqlalchemy/util/compat.py", line 211, in raise_
    raise exception
  File "/home/airflow/.local/lib/python3.12/site-packages/sqlalchemy/orm/session.py", line 3549, in _flush
    flush_context.execute()
  File "/home/airflow/.local/lib/python3.12/site-packages/sqlalchemy/orm/unitofwork.py", line 456, in execute
    rec.execute(self)
  File "/home/airflow/.local/lib/python3.12/site-packages/sqlalchemy/orm/unitofwork.py", line 630, in execute
    util.preloaded.orm_persistence.save_obj(
  File "/home/airflow/.local/lib/python3.12/site-packages/sqlalchemy/orm/persistence.py", line 245, in save_obj
    _emit_insert_statements(
  File "/home/airflow/.local/lib/python3.12/site-packages/sqlalchemy/orm/persistence.py", line 1238, in _emit_insert_statements
    result = connection._execute_20(
             ^^^^^^^^^^^^^^^^^^^^^^^
  File "/home/airflow/.local/lib/python3.12/site-packages/sqlalchemy/engine/base.py", line 1710, in _execute_20
    return meth(self, args_10style, kwargs_10style, execution_options)
           ^^^^^^^^^^^^^^^^^^^^^^^^^^^^^^^^^^^^^^^^^^^^^^^^^^^^^^^^^^^
  File "/home/airflow/.local/lib/python3.12/site-packages/sqlalchemy/sql/elements.py", line 334, in _execute_on_connection
    return connection._execute_clauseelement(
           ^^^^^^^^^^^^^^^^^^^^^^^^^^^^^^^^^^
  File "/home/airflow/.local/lib/python3.12/site-packages/sqlalchemy/engine/base.py", line 1577, in _execute_clauseelement
    ret = self._execute_context(
          ^^^^^^^^^^^^^^^^^^^^^^
  File "/home/airflow/.local/lib/python3.12/site-packages/sqlalchemy/engine/base.py", line 1953, in _execute_context
    self._handle_dbapi_exception(
  File "/home/airflow/.local/lib/python3.12/site-packages/sqlalchemy/engine/base.py", line 2134, in _handle_dbapi_exception
    util.raise_(
  File "/home/airflow/.local/lib/python3.12/site-packages/sqlalchemy/util/compat.py", line 211, in raise_
    raise exception
  File "/home/airflow/.local/lib/python3.12/site-packages/sqlalchemy/engine/base.py", line 1910, in _execute_context
    self.dialect.do_execute(
  File "/home/airflow/.local/lib/python3.12/site-packages/sqlalchemy/engine/default.py", line 736, in do_execute
    cursor.execute(statement, parameters)
sqlalchemy.exc.IntegrityError: (psycopg2.errors.ForeignKeyViolation) insert or update on table "task_fail" violates foreign key constraint "task_fail_ti_fkey"
DETAIL:  Key (dag_id, task_id, run_id, map_index)=(namu_crawling, initialize_if_needed, scheduled__2024-12-22T00:00:00+00:00, -1) is not present in table "task_instance".

[SQL: INSERT INTO task_fail (task_id, dag_id, run_id, map_index, start_date, end_date, duration) VALUES (%(task_id)s, %(dag_id)s, %(run_id)s, %(map_index)s, %(start_date)s, %(end_date)s, %(duration)s) RETURNING task_fail.id]
[parameters: {'task_id': 'initialize_if_needed', 'dag_id': 'namu_crawling', 'run_id': 'scheduled__2024-12-22T00:00:00+00:00', 'map_index': -1, 'start_date': datetime.datetime(2024, 12, 23, 10, 12, 59, 359041, tzinfo=Timezone('UTC')), 'end_date': datetime.datetime(2024, 12, 23, 10, 13, 19, 553671, tzinfo=Timezone('UTC')), 'duration': 20}]
(Background on this error at: https://sqlalche.me/e/14/gkpj)
[2024-12-23T10:13:19.616+0000] {process_utils.py:80} INFO - Process psutil.Process(pid=145, status='terminated', exitcode=1, started='10:12:58') (145) terminated with exit code 1
[2024-12-23T10:13:19.617+0000] {process_utils.py:80} INFO - Process psutil.Process(pid=149, status='terminated', started='10:12:58') (149) terminated with exit code None
[2024-12-23T10:13:29.679+0000] {local_task_job_runner.py:123} INFO - ::group::Pre task execution logs
[2024-12-23T10:13:29.691+0000] {taskinstance.py:2613} INFO - Dependencies all met for dep_context=non-requeueable deps ti=<TaskInstance: namu_crawling.initialize_if_needed scheduled__2024-12-22T00:00:00+00:00 [queued]>
[2024-12-23T10:13:29.697+0000] {taskinstance.py:2613} INFO - Dependencies all met for dep_context=requeueable deps ti=<TaskInstance: namu_crawling.initialize_if_needed scheduled__2024-12-22T00:00:00+00:00 [queued]>
[2024-12-23T10:13:29.698+0000] {taskinstance.py:2866} INFO - Starting attempt 1 of 2
[2024-12-23T10:13:29.706+0000] {taskinstance.py:2889} INFO - Executing <Task(PythonOperator): initialize_if_needed> on 2024-12-22 00:00:00+00:00
[2024-12-23T10:13:29.714+0000] {warnings.py:112} WARNING - /home/***/.local/lib/python3.12/site-packages/***/task/task_runner/standard_task_runner.py:70: DeprecationWarning: This process (pid=247) is multi-threaded, use of fork() may lead to deadlocks in the child.
  pid = os.fork()

[2024-12-23T10:13:29.715+0000] {standard_task_runner.py:72} INFO - Started process 263 to run task
[2024-12-23T10:13:29.715+0000] {standard_task_runner.py:104} INFO - Running: ['***', 'tasks', 'run', 'namu_crawling', 'initialize_if_needed', 'scheduled__2024-12-22T00:00:00+00:00', '--job-id', '9', '--raw', '--subdir', 'DAGS_FOLDER/namu_crawling_dag.py', '--cfg-path', '/tmp/tmp249i3cmv']
[2024-12-23T10:13:29.716+0000] {standard_task_runner.py:105} INFO - Job 9: Subtask initialize_if_needed
[2024-12-23T10:13:29.749+0000] {task_command.py:467} INFO - Running <TaskInstance: namu_crawling.initialize_if_needed scheduled__2024-12-22T00:00:00+00:00 [running]> on host 33f70545a420
[2024-12-23T10:13:29.801+0000] {taskinstance.py:3132} INFO - Exporting env vars: AIRFLOW_CTX_DAG_OWNER='***' AIRFLOW_CTX_DAG_ID='namu_crawling' AIRFLOW_CTX_TASK_ID='initialize_if_needed' AIRFLOW_CTX_EXECUTION_DATE='2024-12-22T00:00:00+00:00' AIRFLOW_CTX_TRY_NUMBER='1' AIRFLOW_CTX_DAG_RUN_ID='scheduled__2024-12-22T00:00:00+00:00'
[2024-12-23T10:13:29.802+0000] {logging_mixin.py:190} INFO - Task instance is in running state
[2024-12-23T10:13:29.803+0000] {logging_mixin.py:190} INFO -  Previous state of the Task instance: queued
[2024-12-23T10:13:29.803+0000] {logging_mixin.py:190} INFO - Current task name:initialize_if_needed state:running start_date:2024-12-23 10:13:29.692337+00:00
[2024-12-23T10:13:29.803+0000] {logging_mixin.py:190} INFO - Dag name:namu_crawling and current dag run status:running
[2024-12-23T10:13:29.804+0000] {taskinstance.py:731} INFO - ::endgroup::
[2024-12-23T10:13:32.168+0000] {logging_mixin.py:190} INFO - Error during initialization: Message: Service /home/***/.cache/selenium/chromedriver/linux64/131.0.6778.204/chromedriver unexpectedly exited. Status code was: 127
[2024-12-23T10:13:32.169+0000] {taskinstance.py:3311} ERROR - Task failed with exception
Traceback (most recent call last):
  File "/home/airflow/.local/lib/python3.12/site-packages/airflow/models/taskinstance.py", line 762, in _execute_task
    result = _execute_callable(context=context, **execute_callable_kwargs)
             ^^^^^^^^^^^^^^^^^^^^^^^^^^^^^^^^^^^^^^^^^^^^^^^^^^^^^^^^^^^^^
  File "/home/airflow/.local/lib/python3.12/site-packages/airflow/models/taskinstance.py", line 733, in _execute_callable
    return ExecutionCallableRunner(
           ^^^^^^^^^^^^^^^^^^^^^^^^
  File "/home/airflow/.local/lib/python3.12/site-packages/airflow/utils/operator_helpers.py", line 252, in run
    return self.func(*args, **kwargs)
           ^^^^^^^^^^^^^^^^^^^^^^^^^^
  File "/home/airflow/.local/lib/python3.12/site-packages/airflow/models/baseoperator.py", line 422, in wrapper
    return func(self, *args, **kwargs)
           ^^^^^^^^^^^^^^^^^^^^^^^^^^^
  File "/home/airflow/.local/lib/python3.12/site-packages/airflow/operators/python.py", line 238, in execute
    return_value = self.execute_callable()
                   ^^^^^^^^^^^^^^^^^^^^^^^
  File "/home/airflow/.local/lib/python3.12/site-packages/airflow/operators/python.py", line 256, in execute_callable
    return runner.run(*self.op_args, **self.op_kwargs)
           ^^^^^^^^^^^^^^^^^^^^^^^^^^^^^^^^^^^^^^^^^^^
  File "/home/airflow/.local/lib/python3.12/site-packages/airflow/utils/operator_helpers.py", line 252, in run
    return self.func(*args, **kwargs)
           ^^^^^^^^^^^^^^^^^^^^^^^^^^
  File "/opt/airflow/dags/namu_crawling_dag.py", line 33, in initialize_and_fetch_recent
    crawler = NamuCrawler()
              ^^^^^^^^^^^^^
  File "/opt/airflow/dags/crawling/sel.py", line 112, in __init__
    self.driver = webdriver.Chrome(options=self.chrome_options)
                  ^^^^^^^^^^^^^^^^^^^^^^^^^^^^^^^^^^^^^^^^^^^^^
  File "/home/airflow/.local/lib/python3.12/site-packages/selenium/webdriver/chrome/webdriver.py", line 45, in __init__
    super().__init__(
  File "/home/airflow/.local/lib/python3.12/site-packages/selenium/webdriver/chromium/webdriver.py", line 55, in __init__
    self.service.start()
  File "/home/airflow/.local/lib/python3.12/site-packages/selenium/webdriver/common/service.py", line 108, in start
    self.assert_process_still_running()
  File "/home/airflow/.local/lib/python3.12/site-packages/selenium/webdriver/common/service.py", line 121, in assert_process_still_running
    raise WebDriverException(f"Service {self._path} unexpectedly exited. Status code was: {return_code}")
selenium.common.exceptions.WebDriverException: Message: Service /home/airflow/.cache/selenium/chromedriver/linux64/131.0.6778.204/chromedriver unexpectedly exited. Status code was: 127

[2024-12-23T10:13:32.182+0000] {logging_mixin.py:190} INFO - Task instance in failure state
[2024-12-23T10:13:32.182+0000] {logging_mixin.py:190} INFO - Task start:2024-12-23 10:13:29.692337+00:00 end:2024-12-23 10:13:32.181755+00:00 duration:2.489418
[2024-12-23T10:13:32.182+0000] {logging_mixin.py:190} INFO - Task:<Task(PythonOperator): initialize_if_needed> dag:<DAG: namu_crawling> dagrun:<DagRun namu_crawling @ 2024-12-22 00:00:00+00:00: scheduled__2024-12-22T00:00:00+00:00, state:running, queued_at: 2024-12-23 10:13:27.335453+00:00. externally triggered: False>
[2024-12-23T10:13:32.182+0000] {logging_mixin.py:190} INFO - Failure caused by Message: Service /home/***/.cache/selenium/chromedriver/linux64/131.0.6778.204/chromedriver unexpectedly exited. Status code was: 127
[2024-12-23T10:13:32.183+0000] {taskinstance.py:1225} INFO - Marking task as UP_FOR_RETRY. dag_id=namu_crawling, task_id=initialize_if_needed, run_id=scheduled__2024-12-22T00:00:00+00:00, execution_date=20241222T000000, start_date=20241223T101329, end_date=20241223T101332
[2024-12-23T10:13:32.193+0000] {taskinstance.py:340} INFO - ::group::Post task execution logs
[2024-12-23T10:13:32.193+0000] {standard_task_runner.py:124} ERROR - Failed to execute job 9 for task initialize_if_needed (Message: Service /home/airflow/.cache/selenium/chromedriver/linux64/131.0.6778.204/chromedriver unexpectedly exited. Status code was: 127
; 263)
Traceback (most recent call last):
  File "/home/airflow/.local/lib/python3.12/site-packages/airflow/task/task_runner/standard_task_runner.py", line 117, in _start_by_fork
    ret = args.func(args, dag=self.dag)
          ^^^^^^^^^^^^^^^^^^^^^^^^^^^^^
  File "/home/airflow/.local/lib/python3.12/site-packages/airflow/cli/cli_config.py", line 49, in command
    return func(*args, **kwargs)
           ^^^^^^^^^^^^^^^^^^^^^
  File "/home/airflow/.local/lib/python3.12/site-packages/airflow/utils/cli.py", line 116, in wrapper
    return f(*args, **kwargs)
           ^^^^^^^^^^^^^^^^^^
  File "/home/airflow/.local/lib/python3.12/site-packages/airflow/cli/commands/task_command.py", line 483, in task_run
    task_return_code = _run_task_by_selected_method(args, _dag, ti)
                       ^^^^^^^^^^^^^^^^^^^^^^^^^^^^^^^^^^^^^^^^^^^^
  File "/home/airflow/.local/lib/python3.12/site-packages/airflow/cli/commands/task_command.py", line 256, in _run_task_by_selected_method
    return _run_raw_task(args, ti)
           ^^^^^^^^^^^^^^^^^^^^^^^
  File "/home/airflow/.local/lib/python3.12/site-packages/airflow/cli/commands/task_command.py", line 341, in _run_raw_task
    return ti._run_raw_task(
           ^^^^^^^^^^^^^^^^^
  File "/home/airflow/.local/lib/python3.12/site-packages/airflow/utils/session.py", line 97, in wrapper
    return func(*args, session=session, **kwargs)
           ^^^^^^^^^^^^^^^^^^^^^^^^^^^^^^^^^^^^^^
  File "/home/airflow/.local/lib/python3.12/site-packages/airflow/models/taskinstance.py", line 3005, in _run_raw_task
    return _run_raw_task(
           ^^^^^^^^^^^^^^
  File "/home/airflow/.local/lib/python3.12/site-packages/airflow/models/taskinstance.py", line 273, in _run_raw_task
    TaskInstance._execute_task_with_callbacks(
  File "/home/airflow/.local/lib/python3.12/site-packages/airflow/models/taskinstance.py", line 3159, in _execute_task_with_callbacks
    result = self._execute_task(context, task_orig)
             ^^^^^^^^^^^^^^^^^^^^^^^^^^^^^^^^^^^^^^
  File "/home/airflow/.local/lib/python3.12/site-packages/airflow/models/taskinstance.py", line 3183, in _execute_task
    return _execute_task(self, context, task_orig)
           ^^^^^^^^^^^^^^^^^^^^^^^^^^^^^^^^^^^^^^^
  File "/home/airflow/.local/lib/python3.12/site-packages/airflow/models/taskinstance.py", line 762, in _execute_task
    result = _execute_callable(context=context, **execute_callable_kwargs)
             ^^^^^^^^^^^^^^^^^^^^^^^^^^^^^^^^^^^^^^^^^^^^^^^^^^^^^^^^^^^^^
  File "/home/airflow/.local/lib/python3.12/site-packages/airflow/models/taskinstance.py", line 733, in _execute_callable
    return ExecutionCallableRunner(
           ^^^^^^^^^^^^^^^^^^^^^^^^
  File "/home/airflow/.local/lib/python3.12/site-packages/airflow/utils/operator_helpers.py", line 252, in run
    return self.func(*args, **kwargs)
           ^^^^^^^^^^^^^^^^^^^^^^^^^^
  File "/home/airflow/.local/lib/python3.12/site-packages/airflow/models/baseoperator.py", line 422, in wrapper
    return func(self, *args, **kwargs)
           ^^^^^^^^^^^^^^^^^^^^^^^^^^^
  File "/home/airflow/.local/lib/python3.12/site-packages/airflow/operators/python.py", line 238, in execute
    return_value = self.execute_callable()
                   ^^^^^^^^^^^^^^^^^^^^^^^
  File "/home/airflow/.local/lib/python3.12/site-packages/airflow/operators/python.py", line 256, in execute_callable
    return runner.run(*self.op_args, **self.op_kwargs)
           ^^^^^^^^^^^^^^^^^^^^^^^^^^^^^^^^^^^^^^^^^^^
  File "/home/airflow/.local/lib/python3.12/site-packages/airflow/utils/operator_helpers.py", line 252, in run
    return self.func(*args, **kwargs)
           ^^^^^^^^^^^^^^^^^^^^^^^^^^
  File "/opt/airflow/dags/namu_crawling_dag.py", line 33, in initialize_and_fetch_recent
    crawler = NamuCrawler()
              ^^^^^^^^^^^^^
  File "/opt/airflow/dags/crawling/sel.py", line 112, in __init__
    self.driver = webdriver.Chrome(options=self.chrome_options)
                  ^^^^^^^^^^^^^^^^^^^^^^^^^^^^^^^^^^^^^^^^^^^^^
  File "/home/airflow/.local/lib/python3.12/site-packages/selenium/webdriver/chrome/webdriver.py", line 45, in __init__
    super().__init__(
  File "/home/airflow/.local/lib/python3.12/site-packages/selenium/webdriver/chromium/webdriver.py", line 55, in __init__
    self.service.start()
  File "/home/airflow/.local/lib/python3.12/site-packages/selenium/webdriver/common/service.py", line 108, in start
    self.assert_process_still_running()
  File "/home/airflow/.local/lib/python3.12/site-packages/selenium/webdriver/common/service.py", line 121, in assert_process_still_running
    raise WebDriverException(f"Service {self._path} unexpectedly exited. Status code was: {return_code}")
selenium.common.exceptions.WebDriverException: Message: Service /home/airflow/.cache/selenium/chromedriver/linux64/131.0.6778.204/chromedriver unexpectedly exited. Status code was: 127

[2024-12-23T10:13:32.215+0000] {local_task_job_runner.py:266} INFO - Task exited with return code 1
[2024-12-23T10:13:32.228+0000] {taskinstance.py:3895} INFO - 0 downstream tasks scheduled from follow-on schedule check
[2024-12-23T10:13:32.229+0000] {local_task_job_runner.py:245} INFO - ::endgroup::
